Workbook

Sheet Raw_Data
A1: EmployeeID | B1: Gender | C1: Location | D1: Department | E1: Role | F1: ContractType | G1: HireSource | H1: HireDate | I1: ExitDate | J1: BirthDate | K1: Salary | L1: Salary_left
A2: E00001 | C2: New York | D2: IT | E2: Sales Executive | F2: Full-Time | G2: career fairs | H2: 40644 | J2: 38567 | K2: $116056 | L2: $116056
A3: E00002 | B3: M | C3: Austin | D3: Research | E3: Sales Executive | F3: Full-Time | H3: 40461 | J3: 27505 | K3: 55k | L3: 55k
A4: E00003 | B4: Female | C4: Seattle | D4: Operations | E4: COO | F4: Part-Time | G4: Recruiting Agency | H4: 42794 | J4: 24668
A5: E00004 | C5: Austin | D5: IT | E5: Developer | F5: full time | H5: 40096 | J5: 24231 | K5: 43k | L5: 43k
A6: E00005 | B6: Male | C6: Denver | D6: IT | E6: Marketing Manager | F6: Full-Time | G6: career fairs | H6: 39983 | J6: 23144
A7: E00006 | D7: Administrative | E7: Developer | F7: Full-Time | G7: job boards | H7: 43104 | J7: 27832 | K7: $112467 | L7: $112467
A8: E00007 | C8: austin | D8: IT | E8: Copywriter | F8: Part-Time | G8: Job Boards | H8: 41319 | I8: 42882
A9: E00008 | B9: FEMALE | C9: New York | D9: Legal | E9: developer | G9: Job Boards | H9: 43023 | I9: 44345 | J9: 34583 | K9: 111222 | L9: 111222
A10: E00009 | D10: Customer Service | E10: Analyst | F10: part time | G10: Job Boards | H10: 43223 | J10: 28678 | K10: $108356 | L10: $108356
A11: E00010 | B11: Male | C11: New york | D11: marketing | E11: developer | F11: Hourly Rate | G11: Job Boards | H11: 40250 | I11: 40485 | J11: 33563 | K11: 40k | L11: 40k
A12: E00011 | C12: austin | E12: Engineer | G12: Online Portal | H12: 42580 | I12: 44498 | K12: 107109 | L12: 107109
A13: E00012 | B13: F | D13: Sales | E13: Marketing Manager | G13: Internal Referral | H13: 42290 | K13: 35k | L13: 35k
A14: E00013 | B14: F | D14: Administrative | E14: Marketing Manager | F14: full time | H14: 42813 | J14: 22130 | K14: 79318 | L14: 79318
A15: E00014 | B15: Male | C15: New york | D15: marketing | E15: COO | G15: Organic | H15: N/A | J15: 25946 | K15: 52k | L15: $75703
A16: E00015 | B16: FEMALE | C16: Austin | D16: Customer Service | E16: Engineer | F16: Full-Time | G16: Career Fairs | H16: 44154 | J16: 26131 | K16: $75703 | L16: 66358
A17: E00016 | B17: FEMALE | C17: Seattle | D17: Research | E17: Sales Executive | F17: full time | G17: Organic | H17: N/A | I17: 41365 | J17: 36453 | K17: $104576
C18: Miami | D18: Marketing | E18: Developer | F18: Full-Time | G18: Organic | H18: 40093 | J18: 33946 | K18: 66358 | L18: 80005
A19: E00018 | B19: male | C19: New york | E19: HR Manager | F19: Full-Time | H19: 39865 | I19: 41288 | J19: 33757
A20: E00019 | B20: FEMALE | D20: marketing | E20: CFO | F20: Full-Time | G20: job boards | H20: 42319 | J20: 34621 | K20: 80005 | L20: 49491
A21: E00020 | B21: Male | C21: New york | D21: IT | E21: Engineer | G21: Organic | H21: 41906 | I21: 42277 | J21: 38387
A22: E00021 | B22: Male | C22: austin | D22: Legal | E22: Accountant | F22: full time | G22: Career Fairs | H22: N/A | I22: 45462 | J22: 34945 | L22: $90148
A23: E00022 | B23: male | D23: Logistics | E23: Developer | F23: part time | H23: 41005 | J23: 24098 | K23: 49491
A24: E00023 | B24: FEMALE | C24: San Diego | D24: Administrative | E24: Copywriter | F24: Full-Time | G24: career fairs | H24: 43786 | J24: 31255 | L24: 110k
A25: E00024 | C25: San Diego | D25: Marketing | E25: CEO | H25: 41033 | J25: 27366 | K25: $90148 | L25: 83205
A26: E00025 | B26: F | C26: New York | D26: Marketing | E26: Developer | H26: 43268 | I26: 44640 | J26: 25689
A27: E00026 | B27: Male | E27: CFO | F27: Part-Time | G27: Internal Referral | H27: 43530 | I27: 45319 | J27: 23460 | K27: 110k | L27: 76k
A28: E00027 | C28: austin | D28: IT | E28: CMO | G28: Career Fairs | H28: 43015 | K28: 83205
A29: E00028 | B29: FEMALE | C29: austin | D29: Research | E29: CEO | G29: Job Boards | H29: 43799 | J29: 28077 | L29: $61880
A30: E00029 | B30: F | C30: San Diego | D30: Administrative | E30: Engineer | G30: Internal Referral | H30: 41064 | I30: 42846 | J30: 27368 | K30: 76k
A31: E00030 | B31: male | C31: Denver | D31: Legal | E31: Sales Executive | G31: Online Portal | H31: N/A | I31: 43885 | J31: 30355 | L31: 59k
A32: E00031 | B32: M | C32: Austin | D32: Sales | E32: Analyst | G32: career fairs | H32: 39845 | J32: 30079
A33: E00032 | B33: M | C33: Austin | D33: Marketing | E33: HR Manager | F33: Part-Time | G33: Organic | H33: 41099 | I33: 41752 | J33: 29578 | K33: $61880 | L33: 31k
A34: E00033 | B34: M | C34: San Diego | D34: Administrative | F34: part time | G34: Job Boards | H34: 40487 | J34: 23735 | L34: 77517
A35: E00034 | B35: FEMALE | C35: Austin | D35: Legal | E35: Accountant | G35: Online Portal | H35: 43357 | J35: 37123 | K35: 59k | L35: 85503
A36: E00035 | C36: Miami | D36: IT | E36: CFO | G36: Career Fairs | H36: 43073 | I36: 43442 | J36: 23623
A37: E00036 | B37: F | C37: Miami | D37: Operations | E37: Accountant | F37: part time | G37: Recruiting Agency | H37: 42211 | J37: 36512 | K37: 31k | L37: 63023
A38: E00037 | B38: FEMALE | C38: austin | D38: IT | F38: Hourly Rate | G38: Career Fairs | H38: 39948 | J38: 29201 | K38: 77517
A39: E00038 | B39: Female | C39: Denver | D39: Marketing | F39: Full-Time | H39: 44034 | J39: 37775 | K39: 85503
A40: E00039 | B40: Male | C40: New York | D40: Production | E40: Analyst | F40: Hourly Rate | G40: Job Boards | H40: 42557 | I40: 42695 | J40: 36236 | L40: 51k
...

Sheet Helper_Sheet
A1: Employee_Id | B1: Value | C1: Gender | D1: Location | E1: Department | F1: Role | G1: Contract Type | H1: Hire Source | I1: HireDate | J1: Analysis | K1: Employee Status | L1: Employee_Age | M1: Salary
A2: =IF(Raw_Data!$A2="","E"&TEXT(ROW()-1,"00000"),Raw_Data!$A2) -> E00001 | B2: E00001 | C2: =IF(OR(PROPER(TRIM(Raw_Data!$B2))="M",PROPER(TRIM(Raw_Data!$B2))="MALE"),"Male", IF(OR(PROPER(TRIM(Raw_Data!$B2))="F",PROPER(TRIM(Raw_Data!$B2))="FEMALE"),"Female","Unknown")) -> Unknown | D2: =IF(TRIM(CLEAN(Raw_Data!$C2))="", "Unknown", PROPER(TRIM(Raw_Data!$C2))) -> New York | E2: =IF(TRIM(Raw_Data!$D2)="IT","IT",PROPER(TRIM(CLEAN(Raw_Data!$D2)))) -> IT | F2: =IF(OR(UPPER(TRIM(Raw_Data!E2))="COO", UPPER(TRIM(Raw_Data!E2))="HR", UPPER(TRIM(Raw_Data!E2))="CEO", UPPER(TRIM(Raw_Data!E2))="CFO", UPPER(TRIM(Raw_Data!E2))="CMO"), UPPER(TRIM(Raw_Data!E2)), PROPER(TRIM(CLEAN(Raw_Data!E2)))) -> Sales Executive | G2: =SUBSTITUTE(PROPER(TRIM(CLEAN(Raw_Data!$F2)))," ","-") -> Full-Time | H2: =PROPER(TRIM(CLEAN(Raw_Data!$G2))) -> Career Fairs | I2: =TRIM(CLEAN(Raw_Data!H2)) -> 40644 | J2: =COUNTIF(I2:I4501,"N/A") -> 238 | K2: =IF(Clean_Data!$I2="","Active","Exited") -> Active | L2: =IF(Clean_Data!$K2="","",DATEDIF(Clean_Data!$K2,TODAY(),"Y")) -> 20 | M2: =IF(Raw_Data!$L2="","",VALUE(SUBSTITUTE(SUBSTITUTE(TRIM(Raw_Data!$L2),"$",""),"k","000"))) -> 116056
A3: =IF(Raw_Data!$A3="","E"&TEXT(ROW()-1,"00000"),Raw_Data!$A3) -> E00002 | B3: E00002 | C3: =IF(OR(PROPER(TRIM(Raw_Data!$B3))="M",PROPER(TRIM(Raw_Data!$B3))="MALE"),"Male", IF(OR(PROPER(TRIM(Raw_Data!$B3))="F",PROPER(TRIM(Raw_Data!$B3))="FEMALE"),"Female","Unknown")) -> Male | D3: =IF(TRIM(CLEAN(Raw_Data!$C3))="", "Unknown", PROPER(TRIM(Raw_Data!$C3))) -> Austin | E3: =IF(TRIM(Raw_Data!$D3)="IT","IT",PROPER(TRIM(CLEAN(Raw_Data!$D3)))) -> Research | F3: =IF(OR(UPPER(TRIM(Raw_Data!E3))="COO", UPPER(TRIM(Raw_Data!E3))="HR", UPPER(TRIM(Raw_Data!E3))="CEO", UPPER(TRIM(Raw_Data!E3))="CFO", UPPER(TRIM(Raw_Data!E3))="CMO"), UPPER(TRIM(Raw_Data!E3)), PROPER(TRIM(CLEAN(Raw_Data!E3)))) -> Sales Executive | G3: =SUBSTITUTE(PROPER(TRIM(CLEAN(Raw_Data!$F3)))," ","-") -> Full-Time | H3: =PROPER(TRIM(CLEAN(Raw_Data!$G3))) | I3: =TRIM(CLEAN(Raw_Data!H3)) -> 40461 | J3: =(238/4501)*100 -> 5.2877138 | K3: =IF(Clean_Data!$I3="","Active","Exited") -> Active | L3: =IF(Clean_Data!$K3="","",DATEDIF(Clean_Data!$K3,TODAY(),"Y")) -> 50 | M3: =IF(Raw_Data!$L3="","",VALUE(SUBSTITUTE(SUBSTITUTE(TRIM(Raw_Data!$L3),"$",""),"k","000"))) -> 55000
A4: =IF(Raw_Data!$A4="","E"&TEXT(ROW()-1,"00000"),Raw_Data!$A4) -> E00003 | B4: E00003 | C4: =IF(OR(PROPER(TRIM(Raw_Data!$B4))="M",PROPER(TRIM(Raw_Data!$B4))="MALE"),"Male", IF(OR(PROPER(TRIM(Raw_Data!$B4))="F",PROPER(TRIM(Raw_Data!$B4))="FEMALE"),"Female","Unknown")) -> Female | D4: =IF(TRIM(CLEAN(Raw_Data!$C4))="", "Unknown", PROPER(TRIM(Raw_Data!$C4))) -> Seattle | E4: =IF(TRIM(Raw_Data!$D4)="IT","IT",PROPER(TRIM(CLEAN(Raw_Data!$D4)))) -> Operations | F4: =IF(OR(UPPER(TRIM(Raw_Data!E4))="COO", UPPER(TRIM(Raw_Data!E4))="HR", UPPER(TRIM(Raw_Data!E4))="CEO", UPPER(TRIM(Raw_Data!E4))="CFO", UPPER(TRIM(Raw_Data!E4))="CMO"), UPPER(TRIM(Raw_Data!E4)), PROPER(TRIM(CLEAN(Raw_Data!E4)))) -> COO | G4: =SUBSTITUTE(PROPER(TRIM(CLEAN(Raw_Data!$F4)))," ","-") -> Part-Time | H4: =PROPER(TRIM(CLEAN(Raw_Data!$G4))) -> Recruiting Agency | I4: =TRIM(CLEAN(Raw_Data!H4)) -> 42794 | K4: =IF(Clean_Data!$I4="","Active","Exited") -> Active | L4: =IF(Clean_Data!$K4="","",DATEDIF(Clean_Data!$K4,TODAY(),"Y")) -> 58 | M4: =IF(Raw_Data!$L4="","",VALUE(SUBSTITUTE(SUBSTITUTE(TRIM(Raw_Data!$L4),"$",""),"k","000")))
A5: =IF(Raw_Data!$A5="","E"&TEXT(ROW()-1,"00000"),Raw_Data!$A5) -> E00004 | B5: E00004 | C5: =IF(OR(PROPER(TRIM(Raw_Data!$B5))="M",PROPER(TRIM(Raw_Data!$B5))="MALE"),"Male", IF(OR(PROPER(TRIM(Raw_Data!$B5))="F",PROPER(TRIM(Raw_Data!$B5))="FEMALE"),"Female","Unknown")) -> Unknown | D5: =IF(TRIM(CLEAN(Raw_Data!$C5))="", "Unknown", PROPER(TRIM(Raw_Data!$C5))) -> Austin | E5: =IF(TRIM(Raw_Data!$D5)="IT","IT",PROPER(TRIM(CLEAN(Raw_Data!$D5)))) -> IT | F5: =IF(OR(UPPER(TRIM(Raw_Data!E5))="COO", UPPER(TRIM(Raw_Data!E5))="HR", UPPER(TRIM(Raw_Data!E5))="CEO", UPPER(TRIM(Raw_Data!E5))="CFO", UPPER(TRIM(Raw_Data!E5))="CMO"), UPPER(TRIM(Raw_Data!E5)), PROPER(TRIM(CLEAN(Raw_Data!E5)))) -> Developer | G5: =SUBSTITUTE(PROPER(TRIM(CLEAN(Raw_Data!$F5)))," ","-") -> Full-Time | H5: =PROPER(TRIM(CLEAN(Raw_Data!$G5))) | I5: =TRIM(CLEAN(Raw_Data!H5)) -> 40096 | K5: =IF(Clean_Data!$I5="","Active","Exited") -> Active | L5: =IF(Clean_Data!$K5="","",DATEDIF(Clean_Data!$K5,TODAY(),"Y")) -> 59 | M5: =IF(Raw_Data!$L5="","",VALUE(SUBSTITUTE(SUBSTITUTE(TRIM(Raw_Data!$L5),"$",""),"k","000"))) -> 43000
A6: =IF(Raw_Data!$A6="","E"&TEXT(ROW()-1,"00000"),Raw_Data!$A6) -> E00005 | B6: E00005 | C6: =IF(OR(PROPER(TRIM(Raw_Data!$B6))="M",PROPER(TRIM(Raw_Data!$B6))="MALE"),"Male", IF(OR(PROPER(TRIM(Raw_Data!$B6))="F",PROPER(TRIM(Raw_Data!$B6))="FEMALE"),"Female","Unknown")) -> Male | D6: =IF(TRIM(CLEAN(Raw_Data!$C6))="", "Unknown", PROPER(TRIM(Raw_Data!$C6))) -> Denver | E6: =IF(TRIM(Raw_Data!$D6)="IT","IT",PROPER(TRIM(CLEAN(Raw_Data!$D6)))) -> IT | F6: =IF(OR(UPPER(TRIM(Raw_Data!E6))="COO", UPPER(TRIM(Raw_Data!E6))="HR", UPPER(TRIM(Raw_Data!E6))="CEO", UPPER(TRIM(Raw_Data!E6))="CFO", UPPER(TRIM(Raw_Data!E6))="CMO"), UPPER(TRIM(Raw_Data!E6)), PROPER(TRIM(CLEAN(Raw_Data!E6)))) -> Marketing Manager | G6: =SUBSTITUTE(PROPER(TRIM(CLEAN(Raw_Data!$F6)))," ","-") -> Full-Time | H6: =PROPER(TRIM(CLEAN(Raw_Data!$G6))) -> Career Fairs | I6: =TRIM(CLEAN(Raw_Data!H6)) -> 39983 | K6: =IF(Clean_Data!$I6="","Active","Exited") -> Active | L6: =IF(Clean_Data!$K6="","",DATEDIF(Clean_Data!$K6,TODAY(),"Y")) -> 62 | M6: =IF(Raw_Data!$L6="","",VALUE(SUBSTITUTE(SUBSTITUTE(TRIM(Raw_Data!$L6),"$",""),"k","000")))
A7: =IF(Raw_Data!$A7="","E"&TEXT(ROW()-1,"00000"),Raw_Data!$A7) -> E00006 | B7: E00006 | C7: =IF(OR(PROPER(TRIM(Raw_Data!$B7))="M",PROPER(TRIM(Raw_Data!$B7))="MALE"),"Male", IF(OR(PROPER(TRIM(Raw_Data!$B7))="F",PROPER(TRIM(Raw_Data!$B7))="FEMALE"),"Female","Unknown")) -> Unknown | D7: =IF(TRIM(CLEAN(Raw_Data!$C7))="", "Unknown", PROPER(TRIM(Raw_Data!$C7))) -> Unknown | E7: =IF(TRIM(Raw_Data!$D7)="IT","IT",PROPER(TRIM(CLEAN(Raw_Data!$D7)))) -> Administrative | F7: =IF(OR(UPPER(TRIM(Raw_Data!E7))="COO", UPPER(TRIM(Raw_Data!E7))="HR", UPPER(TRIM(Raw_Data!E7))="CEO", UPPER(TRIM(Raw_Data!E7))="CFO", UPPER(TRIM(Raw_Data!E7))="CMO"), UPPER(TRIM(Raw_Data!E7)), PROPER(TRIM(CLEAN(Raw_Data!E7)))) -> Developer | G7: =SUBSTITUTE(PROPER(TRIM(CLEAN(Raw_Data!$F7)))," ","-") -> Full-Time | H7: =PROPER(TRIM(CLEAN(Raw_Data!$G7))) -> Job Boards | I7: =TRIM(CLEAN(Raw_Data!H7)) -> 43104 | K7: =IF(Clean_Data!$I7="","Active","Exited") -> Active | L7: =IF(Clean_Data!$K7="","",DATEDIF(Clean_Data!$K7,TODAY(),"Y")) -> 50 | M7: =IF(Raw_Data!$L7="","",VALUE(SUBSTITUTE(SUBSTITUTE(TRIM(Raw_Data!$L7),"$",""),"k","000"))) -> 112467
A8: =IF(Raw_Data!$A8="","E"&TEXT(ROW()-1,"00000"),Raw_Data!$A8) -> E00007 | B8: E00007 | C8: =IF(OR(PROPER(TRIM(Raw_Data!$B8))="M",PROPER(TRIM(Raw_Data!$B8))="MALE"),"Male", IF(OR(PROPER(TRIM(Raw_Data!$B8))="F",PROPER(TRIM(Raw_Data!$B8))="FEMALE"),"Female","Unknown")) -> Unknown | D8: =IF(TRIM(CLEAN(Raw_Data!$C8))="", "Unknown", PROPER(TRIM(Raw_Data!$C8))) -> Austin | E8: =IF(TRIM(Raw_Data!$D8)="IT","IT",PROPER(TRIM(CLEAN(Raw_Data!$D8)))) -> IT | F8: =IF(OR(UPPER(TRIM(Raw_Data!E8))="COO", UPPER(TRIM(Raw_Data!E8))="HR", UPPER(TRIM(Raw_Data!E8))="CEO", UPPER(TRIM(Raw_Data!E8))="CFO", UPPER(TRIM(Raw_Data!E8))="CMO"), UPPER(TRIM(Raw_Data!E8)), PROPER(TRIM(CLEAN(Raw_Data!E8)))) -> Copywriter | G8: =SUBSTITUTE(PROPER(TRIM(CLEAN(Raw_Data!$F8)))," ","-") -> Part-Time | H8: =PROPER(TRIM(CLEAN(Raw_Data!$G8))) -> Job Boards | I8: =TRIM(CLEAN(Raw_Data!H8)) -> 41319 | K8: =IF(Clean_Data!$I8="","Active","Exited") -> Exited | L8: =IF(Clean_Data!$K8="","",DATEDIF(Clean_Data!$K8,TODAY(),"Y")) | M8: =IF(Raw_Data!$L8="","",VALUE(SUBSTITUTE(SUBSTITUTE(TRIM(Raw_Data!$L8),"$",""),"k","000")))
A9: =IF(Raw_Data!$A9="","E"&TEXT(ROW()-1,"00000"),Raw_Data!$A9) -> E00008 | B9: E00008 | C9: =IF(OR(PROPER(TRIM(Raw_Data!$B9))="M",PROPER(TRIM(Raw_Data!$B9))="MALE"),"Male", IF(OR(PROPER(TRIM(Raw_Data!$B9))="F",PROPER(TRIM(Raw_Data!$B9))="FEMALE"),"Female","Unknown")) -> Female | D9: =IF(TRIM(CLEAN(Raw_Data!$C9))="", "Unknown", PROPER(TRIM(Raw_Data!$C9))) -> New York | E9: =IF(TRIM(Raw_Data!$D9)="IT","IT",PROPER(TRIM(CLEAN(Raw_Data!$D9)))) -> Legal | F9: =IF(OR(UPPER(TRIM(Raw_Data!E9))="COO", UPPER(TRIM(Raw_Data!E9))="HR", UPPER(TRIM(Raw_Data!E9))="CEO", UPPER(TRIM(Raw_Data!E9))="CFO", UPPER(TRIM(Raw_Data!E9))="CMO"), UPPER(TRIM(Raw_Data!E9)), PROPER(TRIM(CLEAN(Raw_Data!E9)))) -> Developer | G9: =SUBSTITUTE(PROPER(TRIM(CLEAN(Raw_Data!$F9)))," ","-") | H9: =PROPER(TRIM(CLEAN(Raw_Data!$G9))) -> Job Boards | I9: =TRIM(CLEAN(Raw_Data!H9)) -> 43023 | K9: =IF(Clean_Data!$I9="","Active","Exited") -> Exited | L9: =IF(Clean_Data!$K9="","",DATEDIF(Clean_Data!$K9,TODAY(),"Y")) -> 31 | M9: =IF(Raw_Data!$L9="","",VALUE(SUBSTITUTE(SUBSTITUTE(TRIM(Raw_Data!$L9),"$",""),"k","000"))) -> 111222
A10: =IF(Raw_Data!$A10="","E"&TEXT(ROW()-1,"00000"),Raw_Data!$A10) -> E00009 | B10: E00009 | C10: =IF(OR(PROPER(TRIM(Raw_Data!$B10))="M",PROPER(TRIM(Raw_Data!$B10))="MALE"),"Male", IF(OR(PROPER(TRIM(Raw_Data!$B10))="F",PROPER(TRIM(Raw_Data!$B10))="FEMALE"),"Female","Unknown")) -> Unknown | D10: =IF(TRIM(CLEAN(Raw_Data!$C10))="", "Unknown", PROPER(TRIM(Raw_Data!$C10))) -> Unknown | E10: =IF(TRIM(Raw_Data!$D10)="IT","IT",PROPER(TRIM(CLEAN(Raw_Data!$D10)))) -> Customer Service | F10: =IF(OR(UPPER(TRIM(Raw_Data!E10))="COO", UPPER(TRIM(Raw_Data!E10))="HR", UPPER(TRIM(Raw_Data!E10))="CEO", UPPER(TRIM(Raw_Data!E10))="CFO", UPPER(TRIM(Raw_Data!E10))="CMO"), UPPER(TRIM(Raw_Data!E10)), PROPER(TRIM(CLEAN(Raw_Data!E10)))) -> Analyst | G10: =SUBSTITUTE(PROPER(TRIM(CLEAN(Raw_Data!$F10)))," ","-") -> Part-Time | H10: =PROPER(TRIM(CLEAN(Raw_Data!$G10))) -> Job Boards | I10: =TRIM(CLEAN(Raw_Data!H10)) -> 43223 | K10: =IF(Clean_Data!$I10="","Active","Exited") -> Active | L10: =IF(Clean_Data!$K10="","",DATEDIF(Clean_Data!$K10,TODAY(),"Y")) -> 47 | M10: =IF(Raw_Data!$L10="","",VALUE(SUBSTITUTE(SUBSTITUTE(TRIM(Raw_Data!$L10),"$",""),"k","000"))) -> 108356
A11: =IF(Raw_Data!$A11="","E"&TEXT(ROW()-1,"00000"),Raw_Data!$A11) -> E00010 | B11: E00010 | C11: =IF(OR(PROPER(TRIM(Raw_Data!$B11))="M",PROPER(TRIM(Raw_Data!$B11))="MALE"),"Male", IF(OR(PROPER(TRIM(Raw_Data!$B11))="F",PROPER(TRIM(Raw_Data!$B11))="FEMALE"),"Female","Unknown")) -> Male | D11: =IF(TRIM(CLEAN(Raw_Data!$C11))="", "Unknown", PROPER(TRIM(Raw_Data!$C11))) -> New York | E11: =IF(TRIM(Raw_Data!$D11)="IT","IT",PROPER(TRIM(CLEAN(Raw_Data!$D11)))) -> Marketing | F11: =IF(OR(UPPER(TRIM(Raw_Data!E11))="COO", UPPER(TRIM(Raw_Data!E11))="HR", UPPER(TRIM(Raw_Data!E11))="CEO", UPPER(TRIM(Raw_Data!E11))="CFO", UPPER(TRIM(Raw_Data!E11))="CMO"), UPPER(TRIM(Raw_Data!E11)), PROPER(TRIM(CLEAN(Raw_Data!E11)))) -> Developer | G11: =SUBSTITUTE(PROPER(TRIM(CLEAN(Raw_Data!$F11)))," ","-") -> Hourly-Rate | H11: =PROPER(TRIM(CLEAN(Raw_Data!$G11))) -> Job Boards | I11: =TRIM(CLEAN(Raw_Data!H11)) -> 40250 | K11: =IF(Clean_Data!$I11="","Active","Exited") -> Exited | L11: =IF(Clean_Data!$K11="","",DATEDIF(Clean_Data!$K11,TODAY(),"Y")) -> 34 | M11: =IF(Raw_Data!$L11="","",VALUE(SUBSTITUTE(SUBSTITUTE(TRIM(Raw_Data!$L11),"$",""),"k","000"))) -> 40000
A12: =IF(Raw_Data!$A12="","E"&TEXT(ROW()-1,"00000"),Raw_Data!$A12) -> E00011 | B12: E00011 | C12: =IF(OR(PROPER(TRIM(Raw_Data!$B12))="M",PROPER(TRIM(Raw_Data!$B12))="MALE"),"Male", IF(OR(PROPER(TRIM(Raw_Data!$B12))="F",PROPER(TRIM(Raw_Data!$B12))="FEMALE"),"Female","Unknown")) -> Unknown | D12: =IF(TRIM(CLEAN(Raw_Data!$C12))="", "Unknown", PROPER(TRIM(Raw_Data!$C12))) -> Austin | E12: =IF(TRIM(Raw_Data!$D12)="IT","IT",PROPER(TRIM(CLEAN(Raw_Data!$D12)))) | F12: =IF(OR(UPPER(TRIM(Raw_Data!E12))="COO", UPPER(TRIM(Raw_Data!E12))="HR", UPPER(TRIM(Raw_Data!E12))="CEO", UPPER(TRIM(Raw_Data!E12))="CFO", UPPER(TRIM(Raw_Data!E12))="CMO"), UPPER(TRIM(Raw_Data!E12)), PROPER(TRIM(CLEAN(Raw_Data!E12)))) -> Engineer | G12: =SUBSTITUTE(PROPER(TRIM(CLEAN(Raw_Data!$F12)))," ","-") | H12: =PROPER(TRIM(CLEAN(Raw_Data!$G12))) -> Online Portal | I12: =TRIM(CLEAN(Raw_Data!H12)) -> 42580 | K12: =IF(Clean_Data!$I12="","Active","Exited") -> Exited | L12: =IF(Clean_Data!$K12="","",DATEDIF(Clean_Data!$K12,TODAY(),"Y")) | M12: =IF(Raw_Data!$L12="","",VALUE(SUBSTITUTE(SUBSTITUTE(TRIM(Raw_Data!$L12),"$",""),"k","000"))) -> 107109
A13: =IF(Raw_Data!$A13="","E"&TEXT(ROW()-1,"00000"),Raw_Data!$A13) -> E00012 | B13: E00012 | C13: =IF(OR(PROPER(TRIM(Raw_Data!$B13))="M",PROPER(TRIM(Raw_Data!$B13))="MALE"),"Male", IF(OR(PROPER(TRIM(Raw_Data!$B13))="F",PROPER(TRIM(Raw_Data!$B13))="FEMALE"),"Female","Unknown")) -> Female | D13: =IF(TRIM(CLEAN(Raw_Data!$C13))="", "Unknown", PROPER(TRIM(Raw_Data!$C13))) -> Unknown | E13: =IF(TRIM(Raw_Data!$D13)="IT","IT",PROPER(TRIM(CLEAN(Raw_Data!$D13)))) -> Sales | F13: =IF(OR(UPPER(TRIM(Raw_Data!E13))="COO", UPPER(TRIM(Raw_Data!E13))="HR", UPPER(TRIM(Raw_Data!E13))="CEO", UPPER(TRIM(Raw_Data!E13))="CFO", UPPER(TRIM(Raw_Data!E13))="CMO"), UPPER(TRIM(Raw_Data!E13)), PROPER(TRIM(CLEAN(Raw_Data!E13)))) -> Marketing Manager | G13: =SUBSTITUTE(PROPER(TRIM(CLEAN(Raw_Data!$F13)))," ","-") | H13: =PROPER(TRIM(CLEAN(Raw_Data!$G13))) -> Internal Referral | I13: =TRIM(CLEAN(Raw_Data!H13)) -> 42290 | K13: =IF(Clean_Data!$I13="","Active","Exited") -> Active | L13: =IF(Clean_Data!$K13="","",DATEDIF(Clean_Data!$K13,TODAY(),"Y")) | M13: =IF(Raw_Data!$L13="","",VALUE(SUBSTITUTE(SUBSTITUTE(TRIM(Raw_Data!$L13),"$",""),"k","000"))) -> 35000
A14: =IF(Raw_Data!$A14="","E"&TEXT(ROW()-1,"00000"),Raw_Data!$A14) -> E00013 | B14: E00013 | C14: =IF(OR(PROPER(TRIM(Raw_Data!$B14))="M",PROPER(TRIM(Raw_Data!$B14))="MALE"),"Male", IF(OR(PROPER(TRIM(Raw_Data!$B14))="F",PROPER(TRIM(Raw_Data!$B14))="FEMALE"),"Female","Unknown")) -> Female | D14: =IF(TRIM(CLEAN(Raw_Data!$C14))="", "Unknown", PROPER(TRIM(Raw_Data!$C14))) -> Unknown | E14: =IF(TRIM(Raw_Data!$D14)="IT","IT",PROPER(TRIM(CLEAN(Raw_Data!$D14)))) -> Administrative | F14: =IF(OR(UPPER(TRIM(Raw_Data!E14))="COO", UPPER(TRIM(Raw_Data!E14))="HR", UPPER(TRIM(Raw_Data!E14))="CEO", UPPER(TRIM(Raw_Data!E14))="CFO", UPPER(TRIM(Raw_Data!E14))="CMO"), UPPER(TRIM(Raw_Data!E14)), PROPER(TRIM(CLEAN(Raw_Data!E14)))) -> Marketing Manager | G14: =SUBSTITUTE(PROPER(TRIM(CLEAN(Raw_Data!$F14)))," ","-") -> Full-Time | H14: =PROPER(TRIM(CLEAN(Raw_Data!$G14))) | I14: =TRIM(CLEAN(Raw_Data!H14)) -> 42813 | K14: =IF(Clean_Data!$I14="","Active","Exited") -> Active | L14: =IF(Clean_Data!$K14="","",DATEDIF(Clean_Data!$K14,TODAY(),"Y")) -> 65 | M14: =IF(Raw_Data!$L14="","",VALUE(SUBSTITUTE(SUBSTITUTE(TRIM(Raw_Data!$L14),"$",""),"k","000"))) -> 79318
A15: =IF(Raw_Data!$A15="","E"&TEXT(ROW()-1,"00000"),Raw_Data!$A15) -> E00014 | B15: E00014 | C15: =IF(OR(PROPER(TRIM(Raw_Data!$B15))="M",PROPER(TRIM(Raw_Data!$B15))="MALE"),"Male", IF(OR(PROPER(TRIM(Raw_Data!$B15))="F",PROPER(TRIM(Raw_Data!$B15))="FEMALE"),"Female","Unknown")) -> Male | D15: =IF(TRIM(CLEAN(Raw_Data!$C15))="", "Unknown", PROPER(TRIM(Raw_Data!$C15))) -> New York | E15: =IF(TRIM(Raw_Data!$D15)="IT","IT",PROPER(TRIM(CLEAN(Raw_Data!$D15)))) -> Marketing | F15: =IF(OR(UPPER(TRIM(Raw_Data!E15))="COO", UPPER(TRIM(Raw_Data!E15))="HR", UPPER(TRIM(Raw_Data!E15))="CEO", UPPER(TRIM(Raw_Data!E15))="CFO", UPPER(TRIM(Raw_Data!E15))="CMO"), UPPER(TRIM(Raw_Data!E15)), PROPER(TRIM(CLEAN(Raw_Data!E15)))) -> COO | G15: =SUBSTITUTE(PROPER(TRIM(CLEAN(Raw_Data!$F15)))," ","-") | H15: =PROPER(TRIM(CLEAN(Raw_Data!$G15))) -> Organic | I15: =TRIM(CLEAN(Raw_Data!H15)) -> N/A | K15: =IF(Clean_Data!$I15="","Active","Exited") -> Active | L15: =IF(Clean_Data!$K15="","",DATEDIF(Clean_Data!$K15,TODAY(),"Y")) -> 54 | M15: =IF(Raw_Data!$L15="","",VALUE(SUBSTITUTE(SUBSTITUTE(TRIM(Raw_Data!$L15),"$",""),"k","000"))) -> 75703
... A18: =IF(Raw_Data!$A18="","E"&TEXT(ROW()-1,"00000"),Raw_Data!$A18) -> E00017 | B18: E00017 | C18: =IF(OR(PROPER(TRIM(Raw_Data!$B18))="M",PROPER(TRIM(Raw_Data!$B18))="MALE"),"Male", IF(OR(PROPER(TRIM(Raw_Data!$B18))="F",PROPER(TRIM(Raw_Data!$B18))="FEMALE"),"Female","Unknown")) -> Unknown | D18: =IF(TRIM(CLEAN(Raw_Data!$C18))="", "Unknown", PROPER(TRIM(Raw_Data!$C18))) -> Miami | E18: =IF(TRIM(Raw_Data!$D18)="IT","IT",PROPER(TRIM(CLEAN(Raw_Data!$D18)))) -> Marketing | F18: =IF(OR(UPPER(TRIM(Raw_Data!E18))="COO", UPPER(TRIM(Raw_Data!E18))="HR", UPPER(TRIM(Raw_Data!E18))="CEO", UPPER(TRIM(Raw_Data!E18))="CFO", UPPER(TRIM(Raw_Data!E18))="CMO"), UPPER(TRIM(Raw_Data!E18)), PROPER(TRIM(CLEAN(Raw_Data!E18)))) -> Developer | G18: =SUBSTITUTE(PROPER(TRIM(CLEAN(Raw_Data!$F18)))," ","-") -> Full-Time | H18: =PROPER(TRIM(CLEAN(Raw_Data!$G18))) -> Organic | I18: =TRIM(CLEAN(Raw_Data!H18)) -> 40093 | K18: =IF(Clean_Data!$I18="","Active","Exited") -> Active | L18: =IF(Clean_Data!$K18="","",DATEDIF(Clean_Data!$K18,TODAY(),"Y")) -> 31 | M18: =IF(Raw_Data!$L18="","",VALUE(SUBSTITUTE(SUBSTITUTE(TRIM(Raw_Data!$L18),"$",""),"k","000"))) -> 80005
A19: =IF(Raw_Data!$A19="","E"&TEXT(ROW()-1,"00000"),Raw_Data!$A19) -> E00018 | B19: E00018 | C19: =IF(OR(PROPER(TRIM(Raw_Data!$B19))="M",PROPER(TRIM(Raw_Data!$B19))="MALE"),"Male", IF(OR(PROPER(TRIM(Raw_Data!$B19))="F",PROPER(TRIM(Raw_Data!$B19))="FEMALE"),"Female","Unknown")) -> Male | D19: =IF(TRIM(CLEAN(Raw_Data!$C19))="", "Unknown", PROPER(TRIM(Raw_Data!$C19))) -> New York | E19: =IF(TRIM(Raw_Data!$D19)="IT","IT",PROPER(TRIM(CLEAN(Raw_Data!$D19)))) | F19: =UPPER(LEFT(Raw_Data!E19,2))&MID(PROPER(Raw_Data!E19),3,LEN(Raw_Data!E19)) -> HR Manager | G19: =SUBSTITUTE(PROPER(TRIM(CLEAN(Raw_Data!$F19)))," ","-") -> Full-Time | H19: =PROPER(TRIM(CLEAN(Raw_Data!$G19))) | I19: =TRIM(CLEAN(Raw_Data!H19)) -> 39865 | K19: =IF(Clean_Data!$I19="","Active","Exited") -> Exited | L19: =IF(Clean_Data!$K19="","",DATEDIF(Clean_Data!$K19,TODAY(),"Y")) -> 21 | M19: =IF(Raw_Data!$L19="","",VALUE(SUBSTITUTE(SUBSTITUTE(TRIM(Raw_Data!$L19),"$",""),"k","000")))
A20: =IF(Raw_Data!$A20="","E"&TEXT(ROW()-1,"00000"),Raw_Data!$A20) -> E00019 | B20: E00019 | C20: =IF(OR(PROPER(TRIM(Raw_Data!$B20))="M",PROPER(TRIM(Raw_Data!$B20))="MALE"),"Male", IF(OR(PROPER(TRIM(Raw_Data!$B20))="F",PROPER(TRIM(Raw_Data!$B20))="FEMALE"),"Female","Unknown")) -> Female | D20: =IF(TRIM(CLEAN(Raw_Data!$C20))="", "Unknown", PROPER(TRIM(Raw_Data!$C20))) -> Unknown | E20: =IF(TRIM(Raw_Data!$D20)="IT","IT",PROPER(TRIM(CLEAN(Raw_Data!$D20)))) -> Marketing | F20: =IF(OR(UPPER(TRIM(Raw_Data!E20))="COO", UPPER(TRIM(Raw_Data!E20))="HR", UPPER(TRIM(Raw_Data!E20))="CEO", UPPER(TRIM(Raw_Data!E20))="CFO", UPPER(TRIM(Raw_Data!E20))="CMO"), UPPER(TRIM(Raw_Data!E20)), PROPER(TRIM(CLEAN(Raw_Data!E20)))) -> CFO | G20: =SUBSTITUTE(PROPER(TRIM(CLEAN(Raw_Data!$F20)))," ","-") -> Full-Time | H20: =PROPER(TRIM(CLEAN(Raw_Data!$G20))) -> Job Boards | I20: =TRIM(CLEAN(Raw_Data!H20)) -> 42319 | K20: =IF(Clean_Data!$I20="","Active","Exited") -> Active | L20: =IF(Clean_Data!$K20="","",DATEDIF(Clean_Data!$K20,TODAY(),"Y")) -> 60 | M20: =IF(Raw_Data!$L20="","",VALUE(SUBSTITUTE(SUBSTITUTE(TRIM(Raw_Data!$L20),"$",""),"k","000"))) -> 49491
A21: =IF(Raw_Data!$A21="","E"&TEXT(ROW()-1,"00000"),Raw_Data!$A21) -> E00020 | B21: E00020 | C21: =IF(OR(PROPER(TRIM(Raw_Data!$B21))="M",PROPER(TRIM(Raw_Data!$B21))="MALE"),"Male", IF(OR(PROPER(TRIM(Raw_Data!$B21))="F",PROPER(TRIM(Raw_Data!$B21))="FEMALE"),"Female","Unknown")) -> Male | D21: =IF(TRIM(CLEAN(Raw_Data!$C21))="", "Unknown", PROPER(TRIM(Raw_Data!$C21))) -> New York | E21: =IF(TRIM(Raw_Data!$D21)="IT","IT",PROPER(TRIM(CLEAN(Raw_Data!$D21)))) -> IT | F21: =IF(OR(UPPER(TRIM(Raw_Data!E21))="COO", UPPER(TRIM(Raw_Data!E21))="HR", UPPER(TRIM(Raw_Data!E21))="CEO", UPPER(TRIM(Raw_Data!E21))="CFO", UPPER(TRIM(Raw_Data!E21))="CMO"), UPPER(TRIM(Raw_Data!E21)), PROPER(TRIM(CLEAN(Raw_Data!E21)))) -> Engineer | G21: =SUBSTITUTE(PROPER(TRIM(CLEAN(Raw_Data!$F21)))," ","-") | H21: =PROPER(TRIM(CLEAN(Raw_Data!$G21))) -> Organic | I21: =TRIM(CLEAN(Raw_Data!H21)) -> 41906 | K21: =IF(Clean_Data!$I21="","Active","Exited") -> Active | L21: =IF(Clean_Data!$K21="","",DATEDIF(Clean_Data!$K21,TODAY(),"Y")) -> 40 | M21: =IF(Raw_Data!$L21="","",VALUE(SUBSTITUTE(SUBSTITUTE(TRIM(Raw_Data!$L21),"$",""),"k","000")))
A22: =IF(Raw_Data!$A22="","E"&TEXT(ROW()-1,"00000"),Raw_Data!$A22) -> E00021 | B22: E00021 | C22: =IF(OR(PROPER(TRIM(Raw_Data!$B22))="M",PROPER(TRIM(Raw_Data!$B22))="MALE"),"Male", IF(OR(PROPER(TRIM(Raw_Data!$B22))="F",PROPER(TRIM(Raw_Data!$B22))="FEMALE"),"Female","Unknown")) -> Male | D22: =IF(TRIM(CLEAN(Raw_Data!$C22))="", "Unknown", PROPER(TRIM(Raw_Data!$C22))) -> Austin | E22: =IF(TRIM(Raw_Data!$D22)="IT","IT",PROPER(TRIM(CLEAN(Raw_Data!$D22)))) -> Legal | F22: =IF(OR(UPPER(TRIM(Raw_Data!E22))="COO", UPPER(TRIM(Raw_Data!E22))="HR", UPPER(TRIM(Raw_Data!E22))="CEO", UPPER(TRIM(Raw_Data!E22))="CFO", UPPER(TRIM(Raw_Data!E22))="CMO"), UPPER(TRIM(Raw_Data!E22)), PROPER(TRIM(CLEAN(Raw_Data!E22)))) -> Accountant | G22: =SUBSTITUTE(PROPER(TRIM(CLEAN(Raw_Data!$F22)))," ","-") -> Full-Time | H22: =PROPER(TRIM(CLEAN(Raw_Data!$G22))) -> Career Fairs | I22: =TRIM(CLEAN(Raw_Data!H22)) -> N/A | K22: =IF(Clean_Data!$I22="","Active","Exited") -> Active | L22: =IF(Clean_Data!$K22="","",DATEDIF(Clean_Data!$K22,TODAY(),"Y")) -> 51 | M22: =IF(Raw_Data!$L22="","",VALUE(SUBSTITUTE(SUBSTITUTE(TRIM(Raw_Data!$L22),"$",""),"k","000"))) -> 90148
A23: =IF(Raw_Data!$A23="","E"&TEXT(ROW()-1,"00000"),Raw_Data!$A23) -> E00022 | B23: E00022 | C23: =IF(OR(PROPER(TRIM(Raw_Data!$B23))="M",PROPER(TRIM(Raw_Data!$B23))="MALE"),"Male", IF(OR(PROPER(TRIM(Raw_Data!$B23))="F",PROPER(TRIM(Raw_Data!$B23))="FEMALE"),"Female","Unknown")) -> Male | D23: =IF(TRIM(CLEAN(Raw_Data!$C23))="", "Unknown", PROPER(TRIM(Raw_Data!$C23))) -> Unknown | E23: =IF(TRIM(Raw_Data!$D23)="IT","IT",PROPER(TRIM(CLEAN(Raw_Data!$D23)))) -> Logistics | F23: =IF(OR(UPPER(TRIM(Raw_Data!E23))="COO", UPPER(TRIM(Raw_Data!E23))="HR", UPPER(TRIM(Raw_Data!E23))="CEO", UPPER(TRIM(Raw_Data!E23))="CFO", UPPER(TRIM(Raw_Data!E23))="CMO"), UPPER(TRIM(Raw_Data!E23)), PROPER(TRIM(CLEAN(Raw_Data!E23)))) -> Developer | G23: =SUBSTITUTE(PROPER(TRIM(CLEAN(Raw_Data!$F23)))," ","-") -> Part-Time | H23: =PROPER(TRIM(CLEAN(Raw_Data!$G23))) | I23: =TRIM(CLEAN(Raw_Data!H23)) -> 41005 | K23: =IF(Clean_Data!$I23="","Active","Exited") -> Exited | L23: =IF(Clean_Data!$K23="","",DATEDIF(Clean_Data!$K23,TODAY(),"Y")) -> 55 | M23: =IF(Raw_Data!$L23="","",VALUE(SUBSTITUTE(SUBSTITUTE(TRIM(Raw_Data!$L23),"$",""),"k","000")))
A24: =IF(Raw_Data!$A24="","E"&TEXT(ROW()-1,"00000"),Raw_Data!$A24) -> E00023 | B24: E00023 | C24: =IF(OR(PROPER(TRIM(Raw_Data!$B24))="M",PROPER(TRIM(Raw_Data!$B24))="MALE"),"Male", IF(OR(PROPER(TRIM(Raw_Data!$B24))="F",PROPER(TRIM(Raw_Data!$B24))="FEMALE"),"Female","Unknown")) -> Female | D24: =IF(TRIM(CLEAN(Raw_Data!$C24))="", "Unknown", PROPER(TRIM(Raw_Data!$C24))) -> San Diego | E24: =IF(TRIM(Raw_Data!$D24)="IT","IT",PROPER(TRIM(CLEAN(Raw_Data!$D24)))) -> Administrative | F24: =IF(OR(UPPER(TRIM(Raw_Data!E24))="COO", UPPER(TRIM(Raw_Data!E24))="HR", UPPER(TRIM(Raw_Data!E24))="CEO", UPPER(TRIM(Raw_Data!E24))="CFO", UPPER(TRIM(Raw_Data!E24))="CMO"), UPPER(TRIM(Raw_Data!E24)), PROPER(TRIM(CLEAN(Raw_Data!E24)))) -> Copywriter | G24: =SUBSTITUTE(PROPER(TRIM(CLEAN(Raw_Data!$F24)))," ","-") -> Full-Time | H24: =PROPER(TRIM(CLEAN(Raw_Data!$G24))) -> Career Fairs | I24: =TRIM(CLEAN(Raw_Data!H24)) -> 43786 | K24: =IF(Clean_Data!$I24="","Active","Exited") -> Exited | L24: =IF(Clean_Data!$K24="","",DATEDIF(Clean_Data!$K24,TODAY(),"Y")) -> 61 | M24: =IF(Raw_Data!$L24="","",VALUE(SUBSTITUTE(SUBSTITUTE(TRIM(Raw_Data!$L24),"$",""),"k","000"))) -> 110000
A25: =IF(Raw_Data!$A25="","E"&TEXT(ROW()-1,"00000"),Raw_Data!$A25) -> E00024 | B25: E00024 | C25: =IF(OR(PROPER(TRIM(Raw_Data!$B25))="M",PROPER(TRIM(Raw_Data!$B25))="MALE"),"Male", IF(OR(PROPER(TRIM(Raw_Data!$B25))="F",PROPER(TRIM(Raw_Data!$B25))="FEMALE"),"Female","Unknown")) -> Unknown | D25: =IF(TRIM(CLEAN(Raw_Data!$C25))="", "Unknown", PROPER(TRIM(Raw_Data!$C25))) -> San Diego | E25: =IF(TRIM(Raw_Data!$D25)="IT","IT",PROPER(TRIM(CLEAN(Raw_Data!$D25)))) -> Marketing | F25: =IF(OR(UPPER(TRIM(Raw_Data!E25))="COO", UPPER(TRIM(Raw_Data!E25))="HR", UPPER(TRIM(Raw_Data!E25))="CEO", UPPER(TRIM(Raw_Data!E25))="CFO", UPPER(TRIM(Raw_Data!E25))="CMO"), UPPER(TRIM(Raw_Data!E25)), PROPER(TRIM(CLEAN(Raw_Data!E25)))) -> CEO | G25: =SUBSTITUTE(PROPER(TRIM(CLEAN(Raw_Data!$F25)))," ","-") | H25: =PROPER(TRIM(CLEAN(Raw_Data!$G25))) | I25: =TRIM(CLEAN(Raw_Data!H25)) -> 41033 | K25: =IF(Clean_Data!$I25="","Active","Exited") -> Active | L25: =IF(Clean_Data!$K25="","",DATEDIF(Clean_Data!$K25,TODAY(),"Y")) | M25: =IF(Raw_Data!$L25="","",VALUE(SUBSTITUTE(SUBSTITUTE(TRIM(Raw_Data!$L25),"$",""),"k","000"))) -> 83205
A26: =IF(Raw_Data!$A26="","E"&TEXT(ROW()-1,"00000"),Raw_Data!$A26) -> E00025 | B26: E00025 | C26: =IF(OR(PROPER(TRIM(Raw_Data!$B26))="M",PROPER(TRIM(Raw_Data!$B26))="MALE"),"Male", IF(OR(PROPER(TRIM(Raw_Data!$B26))="F",PROPER(TRIM(Raw_Data!$B26))="FEMALE"),"Female","Unknown")) -> Female | D26: =IF(TRIM(CLEAN(Raw_Data!$C26))="", "Unknown", PROPER(TRIM(Raw_Data!$C26))) -> New York | E26: =IF(TRIM(Raw_Data!$D26)="IT","IT",PROPER(TRIM(CLEAN(Raw_Data!$D26)))) -> Marketing | F26: =IF(OR(UPPER(TRIM(Raw_Data!E26))="COO", UPPER(TRIM(Raw_Data!E26))="HR", UPPER(TRIM(Raw_Data!E26))="CEO", UPPER(TRIM(Raw_Data!E26))="CFO", UPPER(TRIM(Raw_Data!E26))="CMO"), UPPER(TRIM(Raw_Data!E26)), PROPER(TRIM(CLEAN(Raw_Data!E26)))) -> Developer | G26: =SUBSTITUTE(PROPER(TRIM(CLEAN(Raw_Data!$F26)))," ","-") | H26: =PROPER(TRIM(CLEAN(Raw_Data!$G26))) | I26: =TRIM(CLEAN(Raw_Data!H26)) -> 43268 | K26: =IF(Clean_Data!$I26="","Active","Exited") -> Active | L26: =IF(Clean_Data!$K26="","",DATEDIF(Clean_Data!$K26,TODAY(),"Y")) -> 49 | M26: =IF(Raw_Data!$L26="","",VALUE(SUBSTITUTE(SUBSTITUTE(TRIM(Raw_Data!$L26),"$",""),"k","000")))
A27: =IF(Raw_Data!$A27="","E"&TEXT(ROW()-1,"00000"),Raw_Data!$A27) -> E00026 | B27: E00026 | C27: =IF(OR(PROPER(TRIM(Raw_Data!$B27))="M",PROPER(TRIM(Raw_Data!$B27))="MALE"),"Male", IF(OR(PROPER(TRIM(Raw_Data!$B27))="F",PROPER(TRIM(Raw_Data!$B27))="FEMALE"),"Female","Unknown")) -> Male | D27: =IF(TRIM(CLEAN(Raw_Data!$C27))="", "Unknown", PROPER(TRIM(Raw_Data!$C27))) -> Unknown | E27: =IF(TRIM(Raw_Data!$D27)="IT","IT",PROPER(TRIM(CLEAN(Raw_Data!$D27)))) | F27: =IF(OR(UPPER(TRIM(Raw_Data!E27))="COO", UPPER(TRIM(Raw_Data!E27))="HR", UPPER(TRIM(Raw_Data!E27))="CEO", UPPER(TRIM(Raw_Data!E27))="CFO", UPPER(TRIM(Raw_Data!E27))="CMO"), UPPER(TRIM(Raw_Data!E27)), PROPER(TRIM(CLEAN(Raw_Data!E27)))) -> CFO | G27: =SUBSTITUTE(PROPER(TRIM(CLEAN(Raw_Data!$F27)))," ","-") -> Part-Time | H27: =PROPER(TRIM(CLEAN(Raw_Data!$G27))) -> Internal Referral | I27: =TRIM(CLEAN(Raw_Data!H27)) -> 43530 | K27: =IF(Clean_Data!$I27="","Active","Exited") -> Exited | L27: =IF(Clean_Data!$K27="","",DATEDIF(Clean_Data!$K27,TODAY(),"Y")) -> 51 | M27: =IF(Raw_Data!$L27="","",VALUE(SUBSTITUTE(SUBSTITUTE(TRIM(Raw_Data!$L27),"$",""),"k","000"))) -> 76000
A28: =IF(Raw_Data!$A28="","E"&TEXT(ROW()-1,"00000"),Raw_Data!$A28) -> E00027 | B28: E00027 | C28: =IF(OR(PROPER(TRIM(Raw_Data!$B28))="M",PROPER(TRIM(Raw_Data!$B28))="MALE"),"Male", IF(OR(PROPER(TRIM(Raw_Data!$B28))="F",PROPER(TRIM(Raw_Data!$B28))="FEMALE"),"Female","Unknown")) -> Unknown | D28: =IF(TRIM(CLEAN(Raw_Data!$C28))="", "Unknown", PROPER(TRIM(Raw_Data!$C28))) -> Austin | E28: =IF(TRIM(Raw_Data!$D28)="IT","IT",PROPER(TRIM(CLEAN(Raw_Data!$D28)))) -> IT | F28: =IF(OR(UPPER(TRIM(Raw_Data!E28))="COO", UPPER(TRIM(Raw_Data!E28))="HR", UPPER(TRIM(Raw_Data!E28))="CEO", UPPER(TRIM(Raw_Data!E28))="CFO", UPPER(TRIM(Raw_Data!E28))="CMO"), UPPER(TRIM(Raw_Data!E28)), PROPER(TRIM(CLEAN(Raw_Data!E28)))) -> CMO | G28: =SUBSTITUTE(PROPER(TRIM(CLEAN(Raw_Data!$F28)))," ","-") | H28: =PROPER(TRIM(CLEAN(Raw_Data!$G28))) -> Career Fairs | I28: =TRIM(CLEAN(Raw_Data!H28)) -> 43015 | K28: =IF(Clean_Data!$I28="","Active","Exited") -> Active | L28: =IF(Clean_Data!$K28="","",DATEDIF(Clean_Data!$K28,TODAY(),"Y")) -> 43 | M28: =IF(Raw_Data!$L28="","",VALUE(SUBSTITUTE(SUBSTITUTE(TRIM(Raw_Data!$L28),"$",""),"k","000")))
A29: =IF(Raw_Data!$A29="","E"&TEXT(ROW()-1,"00000"),Raw_Data!$A29) -> E00028 | B29: E00028 | C29: =IF(OR(PROPER(TRIM(Raw_Data!$B29))="M",PROPER(TRIM(Raw_Data!$B29))="MALE"),"Male", IF(OR(PROPER(TRIM(Raw_Data!$B29))="F",PROPER(TRIM(Raw_Data!$B29))="FEMALE"),"Female","Unknown")) -> Female | D29: =IF(TRIM(CLEAN(Raw_Data!$C29))="", "Unknown", PROPER(TRIM(Raw_Data!$C29))) -> Austin | E29: =IF(TRIM(Raw_Data!$D29)="IT","IT",PROPER(TRIM(CLEAN(Raw_Data!$D29)))) -> Research | F29: =IF(OR(UPPER(TRIM(Raw_Data!E29))="COO", UPPER(TRIM(Raw_Data!E29))="HR", UPPER(TRIM(Raw_Data!E29))="CEO", UPPER(TRIM(Raw_Data!E29))="CFO", UPPER(TRIM(Raw_Data!E29))="CMO"), UPPER(TRIM(Raw_Data!E29)), PROPER(TRIM(CLEAN(Raw_Data!E29)))) -> CEO | G29: =SUBSTITUTE(PROPER(TRIM(CLEAN(Raw_Data!$F29)))," ","-") | H29: =PROPER(TRIM(CLEAN(Raw_Data!$G29))) -> Job Boards | I29: =TRIM(CLEAN(Raw_Data!H29)) -> 43799 | K29: =IF(Clean_Data!$I29="","Active","Exited") -> Exited | L29: =IF(Clean_Data!$K29="","",DATEDIF(Clean_Data!$K29,TODAY(),"Y")) -> 45 | M29: =IF(Raw_Data!$L29="","",VALUE(SUBSTITUTE(SUBSTITUTE(TRIM(Raw_Data!$L29),"$",""),"k","000"))) -> 61880
A30: =IF(Raw_Data!$A30="","E"&TEXT(ROW()-1,"00000"),Raw_Data!$A30) -> E00029 | B30: E00029 | C30: =IF(OR(PROPER(TRIM(Raw_Data!$B30))="M",PROPER(TRIM(Raw_Data!$B30))="MALE"),"Male", IF(OR(PROPER(TRIM(Raw_Data!$B30))="F",PROPER(TRIM(Raw_Data!$B30))="FEMALE"),"Female","Unknown")) -> Female | D30: =IF(TRIM(CLEAN(Raw_Data!$C30))="", "Unknown", PROPER(TRIM(Raw_Data!$C30))) -> San Diego | E30: =IF(TRIM(Raw_Data!$D30)="IT","IT",PROPER(TRIM(CLEAN(Raw_Data!$D30)))) -> Administrative | F30: =IF(OR(UPPER(TRIM(Raw_Data!E30))="COO", UPPER(TRIM(Raw_Data!E30))="HR", UPPER(TRIM(Raw_Data!E30))="CEO", UPPER(TRIM(Raw_Data!E30))="CFO", UPPER(TRIM(Raw_Data!E30))="CMO"), UPPER(TRIM(Raw_Data!E30)), PROPER(TRIM(CLEAN(Raw_Data!E30)))) -> Engineer | G30: =SUBSTITUTE(PROPER(TRIM(CLEAN(Raw_Data!$F30)))," ","-") | H30: =PROPER(TRIM(CLEAN(Raw_Data!$G30))) -> Internal Referral | I30: =TRIM(CLEAN(Raw_Data!H30)) -> 41064 | K30: =IF(Clean_Data!$I30="","Active","Exited") -> Active | L30: =IF(Clean_Data!$K30="","",DATEDIF(Clean_Data!$K30,TODAY(),"Y")) -> 61 | M30: =IF(Raw_Data!$L30="","",VALUE(SUBSTITUTE(SUBSTITUTE(TRIM(Raw_Data!$L30),"$",""),"k","000")))
A31: =IF(Raw_Data!$A31="","E"&TEXT(ROW()-1,"00000"),Raw_Data!$A31) -> E00030 | B31: E00030 | C31: =IF(OR(PROPER(TRIM(Raw_Data!$B31))="M",PROPER(TRIM(Raw_Data!$B31))="MALE"),"Male", IF(OR(PROPER(TRIM(Raw_Data!$B31))="F",PROPER(TRIM(Raw_Data!$B31))="FEMALE"),"Female","Unknown")) -> Male | D31: =IF(TRIM(CLEAN(Raw_Data!$C31))="", "Unknown", PROPER(TRIM(Raw_Data!$C31))) -> Denver | E31: =IF(TRIM(Raw_Data!$D31)="IT","IT",PROPER(TRIM(CLEAN(Raw_Data!$D31)))) -> Legal | F31: =IF(OR(UPPER(TRIM(Raw_Data!E31))="COO", UPPER(TRIM(Raw_Data!E31))="HR", UPPER(TRIM(Raw_Data!E31))="CEO", UPPER(TRIM(Raw_Data!E31))="CFO", UPPER(TRIM(Raw_Data!E31))="CMO"), UPPER(TRIM(Raw_Data!E31)), PROPER(TRIM(CLEAN(Raw_Data!E31)))) -> Sales Executive | G31: =SUBSTITUTE(PROPER(TRIM(CLEAN(Raw_Data!$F31)))," ","-") | H31: =PROPER(TRIM(CLEAN(Raw_Data!$G31))) -> Online Portal | I31: =TRIM(CLEAN(Raw_Data!H31)) -> N/A | K31: =IF(Clean_Data!$I31="","Active","Exited") -> Active | L31: =IF(Clean_Data!$K31="","",DATEDIF(Clean_Data!$K31,TODAY(),"Y")) -> 24 | M31: =IF(Raw_Data!$L31="","",VALUE(SUBSTITUTE(SUBSTITUTE(TRIM(Raw_Data!$L31),"$",""),"k","000"))) -> 59000
A32: =IF(Raw_Data!$A32="","E"&TEXT(ROW()-1,"00000"),Raw_Data!$A32) -> E00031 | B32: E00031 | C32: =IF(OR(PROPER(TRIM(Raw_Data!$B32))="M",PROPER(TRIM(Raw_Data!$B32))="MALE"),"Male", IF(OR(PROPER(TRIM(Raw_Data!$B32))="F",PROPER(TRIM(Raw_Data!$B32))="FEMALE"),"Female","Unknown")) -> Male | D32: =IF(TRIM(CLEAN(Raw_Data!$C32))="", "Unknown", PROPER(TRIM(Raw_Data!$C32))) -> Austin | E32: =IF(TRIM(Raw_Data!$D32)="IT","IT",PROPER(TRIM(CLEAN(Raw_Data!$D32)))) -> Sales | F32: =IF(OR(UPPER(TRIM(Raw_Data!E32))="COO", UPPER(TRIM(Raw_Data!E32))="HR", UPPER(TRIM(Raw_Data!E32))="CEO", UPPER(TRIM(Raw_Data!E32))="CFO", UPPER(TRIM(Raw_Data!E32))="CMO"), UPPER(TRIM(Raw_Data!E32)), PROPER(TRIM(CLEAN(Raw_Data!E32)))) -> Analyst | G32: =SUBSTITUTE(PROPER(TRIM(CLEAN(Raw_Data!$F32)))," ","-") | H32: =PROPER(TRIM(CLEAN(Raw_Data!$G32))) -> Career Fairs | I32: =TRIM(CLEAN(Raw_Data!H32)) -> 39845 | K32: =IF(Clean_Data!$I32="","Active","Exited") -> Exited | L32: =IF(Clean_Data!$K32="","",DATEDIF(Clean_Data!$K32,TODAY(),"Y")) -> 61 | M32: =IF(Raw_Data!$L32="","",VALUE(SUBSTITUTE(SUBSTITUTE(TRIM(Raw_Data!$L32),"$",""),"k","000")))
A33: =IF(Raw_Data!$A33="","E"&TEXT(ROW()-1,"00000"),Raw_Data!$A33) -> E00032 | B33: E00032 | C33: =IF(OR(PROPER(TRIM(Raw_Data!$B33))="M",PROPER(TRIM(Raw_Data!$B33))="MALE"),"Male", IF(OR(PROPER(TRIM(Raw_Data!$B33))="F",PROPER(TRIM(Raw_Data!$B33))="FEMALE"),"Female","Unknown")) -> Male | D33: =IF(TRIM(CLEAN(Raw_Data!$C33))="", "Unknown", PROPER(TRIM(Raw_Data!$C33))) -> Austin | E33: =IF(TRIM(Raw_Data!$D33)="IT","IT",PROPER(TRIM(CLEAN(Raw_Data!$D33)))) -> Marketing | F33: =UPPER(LEFT(Raw_Data!E33,2))&MID(PROPER(Raw_Data!E33),3,LEN(Raw_Data!E33)) -> HR Manager | G33: =SUBSTITUTE(PROPER(TRIM(CLEAN(Raw_Data!$F33)))," ","-") -> Part-Time | H33: =PROPER(TRIM(CLEAN(Raw_Data!$G33))) -> Organic | I33: =TRIM(CLEAN(Raw_Data!H33)) -> 41099 | K33: =IF(Clean_Data!$I33="","Active","Exited") -> Active | L33: =IF(Clean_Data!$K33="","",DATEDIF(Clean_Data!$K33,TODAY(),"Y")) -> 26 | M33: =IF(Raw_Data!$L33="","",VALUE(SUBSTITUTE(SUBSTITUTE(TRIM(Raw_Data!$L33),"$",""),"k","000"))) -> 31000
A34: =IF(Raw_Data!$A34="","E"&TEXT(ROW()-1,"00000"),Raw_Data!$A34) -> E00033 | B34: E00033 | C34: =IF(OR(PROPER(TRIM(Raw_Data!$B34))="M",PROPER(TRIM(Raw_Data!$B34))="MALE"),"Male", IF(OR(PROPER(TRIM(Raw_Data!$B34))="F",PROPER(TRIM(Raw_Data!$B34))="FEMALE"),"Female","Unknown")) -> Male | D34: =IF(TRIM(CLEAN(Raw_Data!$C34))="", "Unknown", PROPER(TRIM(Raw_Data!$C34))) -> San Diego | E34: =IF(TRIM(Raw_Data!$D34)="IT","IT",PROPER(TRIM(CLEAN(Raw_Data!$D34)))) -> Administrative | F34: Unknown | G34: =SUBSTITUTE(PROPER(TRIM(CLEAN(Raw_Data!$F34)))," ","-") -> Part-Time | H34: =PROPER(TRIM(CLEAN(Raw_Data!$G34))) -> Job Boards | I34: =TRIM(CLEAN(Raw_Data!H34)) -> 40487 | K34: =IF(Clean_Data!$I34="","Active","Exited") -> Active | L34: =IF(Clean_Data!$K34="","",DATEDIF(Clean_Data!$K34,TODAY(),"Y")) -> 46 | M34: =IF(Raw_Data!$L34="","",VALUE(SUBSTITUTE(SUBSTITUTE(TRIM(Raw_Data!$L34),"$",""),"k","000"))) -> 77517
A35: =IF(Raw_Data!$A35="","E"&TEXT(ROW()-1,"00000"),Raw_Data!$A35) -> E00034 | B35: E00034 | C35: =IF(OR(PROPER(TRIM(Raw_Data!$B35))="M",PROPER(TRIM(Raw_Data!$B35))="MALE"),"Male", IF(OR(PROPER(TRIM(Raw_Data!$B35))="F",PROPER(TRIM(Raw_Data!$B35))="FEMALE"),"Female","Unknown")) -> Female | D35: =IF(TRIM(CLEAN(Raw_Data!$C35))="", "Unknown", PROPER(TRIM(Raw_Data!$C35))) -> Austin | E35: =IF(TRIM(Raw_Data!$D35)="IT","IT",PROPER(TRIM(CLEAN(Raw_Data!$D35)))) -> Legal | F35: =IF(OR(UPPER(TRIM(Raw_Data!E35))="COO", UPPER(TRIM(Raw_Data!E35))="HR", UPPER(TRIM(Raw_Data!E35))="CEO", UPPER(TRIM(Raw_Data!E35))="CFO", UPPER(TRIM(Raw_Data!E35))="CMO"), UPPER(TRIM(Raw_Data!E35)), PROPER(TRIM(CLEAN(Raw_Data!E35)))) -> Accountant | G35: =SUBSTITUTE(PROPER(TRIM(CLEAN(Raw_Data!$F35)))," ","-") | H35: =PROPER(TRIM(CLEAN(Raw_Data!$G35))) -> Online Portal | I35: =TRIM(CLEAN(Raw_Data!H35)) -> 43357 | K35: =IF(Clean_Data!$I35="","Active","Exited") -> Active | L35: =IF(Clean_Data!$K35="","",DATEDIF(Clean_Data!$K35,TODAY(),"Y")) -> 22 | M35: =IF(Raw_Data!$L35="","",VALUE(SUBSTITUTE(SUBSTITUTE(TRIM(Raw_Data!$L35),"$",""),"k","000"))) -> 85503
A36: =IF(Raw_Data!$A36="","E"&TEXT(ROW()-1,"00000"),Raw_Data!$A36) -> E00035 | B36: E00035 | C36: =IF(OR(PROPER(TRIM(Raw_Data!$B36))="M",PROPER(TRIM(Raw_Data!$B36))="MALE"),"Male", IF(OR(PROPER(TRIM(Raw_Data!$B36))="F",PROPER(TRIM(Raw_Data!$B36))="FEMALE"),"Female","Unknown")) -> Unknown | D36: =IF(TRIM(CLEAN(Raw_Data!$C36))="", "Unknown", PROPER(TRIM(Raw_Data!$C36))) -> Miami | E36: =IF(TRIM(Raw_Data!$D36)="IT","IT",PROPER(TRIM(CLEAN(Raw_Data!$D36)))) -> IT | F36: =IF(OR(UPPER(TRIM(Raw_Data!E36))="COO", UPPER(TRIM(Raw_Data!E36))="HR", UPPER(TRIM(Raw_Data!E36))="CEO", UPPER(TRIM(Raw_Data!E36))="CFO", UPPER(TRIM(Raw_Data!E36))="CMO"), UPPER(TRIM(Raw_Data!E36)), PROPER(TRIM(CLEAN(Raw_Data!E36)))) -> CFO | G36: =SUBSTITUTE(PROPER(TRIM(CLEAN(Raw_Data!$F36)))," ","-") | H36: =PROPER(TRIM(CLEAN(Raw_Data!$G36))) -> Career Fairs | I36: =TRIM(CLEAN(Raw_Data!H36)) -> 43073 | K36: =IF(Clean_Data!$I36="","Active","Exited") -> Exited | L36: =IF(Clean_Data!$K36="","",DATEDIF(Clean_Data!$K36,TODAY(),"Y")) -> 27 | M36: =IF(Raw_Data!$L36="","",VALUE(SUBSTITUTE(SUBSTITUTE(TRIM(Raw_Data!$L36),"$",""),"k","000")))
A37: =IF(Raw_Data!$A37="","E"&TEXT(ROW()-1,"00000"),Raw_Data!$A37) -> E00036 | B37: E00036 | C37: =IF(OR(PROPER(TRIM(Raw_Data!$B37))="M",PROPER(TRIM(Raw_Data!$B37))="MALE"),"Male", IF(OR(PROPER(TRIM(Raw_Data!$B37))="F",PROPER(TRIM(Raw_Data!$B37))="FEMALE"),"Female","Unknown")) -> Female | D37: =IF(TRIM(CLEAN(Raw_Data!$C37))="", "Unknown", PROPER(TRIM(Raw_Data!$C37))) -> Miami | E37: =IF(TRIM(Raw_Data!$D37)="IT","IT",PROPER(TRIM(CLEAN(Raw_Data!$D37)))) -> Operations | F37: =IF(OR(UPPER(TRIM(Raw_Data!E37))="COO", UPPER(TRIM(Raw_Data!E37))="HR", UPPER(TRIM(Raw_Data!E37))="CEO", UPPER(TRIM(Raw_Data!E37))="CFO", UPPER(TRIM(Raw_Data!E37))="CMO"), UPPER(TRIM(Raw_Data!E37)), PROPER(TRIM(CLEAN(Raw_Data!E37)))) -> Accountant | G37: =SUBSTITUTE(PROPER(TRIM(CLEAN(Raw_Data!$F37)))," ","-") -> Part-Time | H37: =PROPER(TRIM(CLEAN(Raw_Data!$G37))) -> Recruiting Agency | I37: =TRIM(CLEAN(Raw_Data!H37)) -> 42211 | K37: =IF(Clean_Data!$I37="","Active","Exited") -> Exited | L37: =IF(Clean_Data!$K37="","",DATEDIF(Clean_Data!$K37,TODAY(),"Y")) -> 62 | M37: =IF(Raw_Data!$L37="","",VALUE(SUBSTITUTE(SUBSTITUTE(TRIM(Raw_Data!$L37),"$",""),"k","000"))) -> 63023
A38: =IF(Raw_Data!$A38="","E"&TEXT(ROW()-1,"00000"),Raw_Data!$A38) -> E00037 | B38: E00037 | C38: =IF(OR(PROPER(TRIM(Raw_Data!$B38))="M",PROPER(TRIM(Raw_Data!$B38))="MALE"),"Male", IF(OR(PROPER(TRIM(Raw_Data!$B38))="F",PROPER(TRIM(Raw_Data!$B38))="FEMALE"),"Female","Unknown")) -> Female | D38: =IF(TRIM(CLEAN(Raw_Data!$C38))="", "Unknown", PROPER(TRIM(Raw_Data!$C38))) -> Austin | E38: =IF(TRIM(Raw_Data!$D38)="IT","IT",PROPER(TRIM(CLEAN(Raw_Data!$D38)))) -> IT | F38: Unknown | G38: =SUBSTITUTE(PROPER(TRIM(CLEAN(Raw_Data!$F38)))," ","-") -> Hourly-Rate | H38: =PROPER(TRIM(CLEAN(Raw_Data!$G38))) -> Career Fairs | I38: =TRIM(CLEAN(Raw_Data!H38)) -> 39948 | K38: =IF(Clean_Data!$I38="","Active","Exited") -> Exited | L38: =IF(Clean_Data!$K38="","",DATEDIF(Clean_Data!$K38,TODAY(),"Y")) -> 63 | M38: =IF(Raw_Data!$L38="","",VALUE(SUBSTITUTE(SUBSTITUTE(TRIM(Raw_Data!$L38),"$",""),"k","000")))
A39: =IF(Raw_Data!$A39="","E"&TEXT(ROW()-1,"00000"),Raw_Data!$A39) -> E00038 | B39: E00038 | C39: =IF(OR(PROPER(TRIM(Raw_Data!$B39))="M",PROPER(TRIM(Raw_Data!$B39))="MALE"),"Male", IF(OR(PROPER(TRIM(Raw_Data!$B39))="F",PROPER(TRIM(Raw_Data!$B39))="FEMALE"),"Female","Unknown")) -> Female | D39: =IF(TRIM(CLEAN(Raw_Data!$C39))="", "Unknown", PROPER(TRIM(Raw_Data!$C39))) -> Denver | E39: =IF(TRIM(Raw_Data!$D39)="IT","IT",PROPER(TRIM(CLEAN(Raw_Data!$D39)))) -> Marketing | F39: Unknown | G39: =SUBSTITUTE(PROPER(TRIM(CLEAN(Raw_Data!$F39)))," ","-") -> Full-Time | H39: =PROPER(TRIM(CLEAN(Raw_Data!$G39))) | I39: =TRIM(CLEAN(Raw_Data!H39)) -> 44034 | K39: =IF(Clean_Data!$I39="","Active","Exited") -> Active | L39: =IF(Clean_Data!$K39="","",DATEDIF(Clean_Data!$K39,TODAY(),"Y")) -> 41 | M39: =IF(Raw_Data!$L39="","",VALUE(SUBSTITUTE(SUBSTITUTE(TRIM(Raw_Data!$L39),"$",""),"k","000")))
A40: =IF(Raw_Data!$A40="","E"&TEXT(ROW()-1,"00000"),Raw_Data!$A40) -> E00039 | B40: E00039 | C40: =IF(OR(PROPER(TRIM(Raw_Data!$B40))="M",PROPER(TRIM(Raw_Data!$B40))="MALE"),"Male", IF(OR(PROPER(TRIM(Raw_Data!$B40))="F",PROPER(TRIM(Raw_Data!$B40))="FEMALE"),"Female","Unknown")) -> Male | D40: =IF(TRIM(CLEAN(Raw_Data!$C40))="", "Unknown", PROPER(TRIM(Raw_Data!$C40))) -> New York | E40: =IF(TRIM(Raw_Data!$D40)="IT","IT",PROPER(TRIM(CLEAN(Raw_Data!$D40)))) -> Production | F40: =IF(OR(UPPER(TRIM(Raw_Data!E40))="COO", UPPER(TRIM(Raw_Data!E40))="HR", UPPER(TRIM(Raw_Data!E40))="CEO", UPPER(TRIM(Raw_Data!E40))="CFO", UPPER(TRIM(Raw_Data!E40))="CMO"), UPPER(TRIM(Raw_Data!E40)), PROPER(TRIM(CLEAN(Raw_Data!E40)))) -> Analyst | G40: =SUBSTITUTE(PROPER(TRIM(CLEAN(Raw_Data!$F40)))," ","-") -> Hourly-Rate | H40: =PROPER(TRIM(CLEAN(Raw_Data!$G40))) -> Job Boards | I40: =TRIM(CLEAN(Raw_Data!H40)) -> 42557 | K40: =IF(Clean_Data!$I40="","Active","Exited") -> Active | L40: =IF(Clean_Data!$K40="","",DATEDIF(Clean_Data!$K40,TODAY(),"Y")) -> 38 | M40: =IF(Raw_Data!$L40="","",VALUE(SUBSTITUTE(SUBSTITUTE(TRIM(Raw_Data!$L40),"$",""),"k","000"))) -> 51000
A41: =IF(Raw_Data!$A41="","E"&TEXT(ROW()-1,"00000"),Raw_Data!$A41) -> E00040 | B41: E00040 | C41: =IF(OR(PROPER(TRIM(Raw_Data!$B41))="M",PROPER(TRIM(Raw_Data!$B41))="MALE"),"Male", IF(OR(PROPER(TRIM(Raw_Data!$B41))="F",PROPER(TRIM(Raw_Data!$B41))="FEMALE"),"Female","Unknown")) -> Male | D41: =IF(TRIM(CLEAN(Raw_Data!$C41))="", "Unknown", PROPER(TRIM(Raw_Data!$C41))) -> San Diego | E41: =IF(TRIM(Raw_Data!$D41)="IT","IT",PROPER(TRIM(CLEAN(Raw_Data!$D41)))) -> Logistics | F41: =IF(OR(UPPER(TRIM(Raw_Data!E41))="COO", UPPER(TRIM(Raw_Data!E41))="HR", UPPER(TRIM(Raw_Data!E41))="CEO", UPPER(TRIM(Raw_Data!E41))="CFO", UPPER(TRIM(Raw_Data!E41))="CMO"), UPPER(TRIM(Raw_Data!E41)), PROPER(TRIM(CLEAN(Raw_Data!E41)))) -> CEO | G41: =SUBSTITUTE(PROPER(TRIM(CLEAN(Raw_Data!$F41)))," ","-") | H41: =PROPER(TRIM(CLEAN(Raw_Data!$G41))) -> Recruiting Agency | I41: =TRIM(CLEAN(Raw_Data!H41)) -> 41683 | K41: =IF(Clean_Data!$I41="","Active","Exited") -> Active | L41: =IF(Clean_Data!$K41="","",DATEDIF(Clean_Data!$K41,TODAY(),"Y")) -> 65 | M41: =IF(Raw_Data!$L41="","",VALUE(SUBSTITUTE(SUBSTITUTE(TRIM(Raw_Data!$L41),"$",""),"k","000"))) -> 102517
A42: =IF(Raw_Data!$A42="","E"&TEXT(ROW()-1,"00000"),Raw_Data!$A42) -> E00041 | B42: E00041 | C42: =IF(OR(PROPER(TRIM(Raw_Data!$B42))="M",PROPER(TRIM(Raw_Data!$B42))="MALE"),"Male", IF(OR(PROPER(TRIM(Raw_Data!$B42))="F",PROPER(TRIM(Raw_Data!$B42))="FEMALE"),"Female","Unknown")) -> Female | D42: =IF(TRIM(CLEAN(Raw_Data!$C42))="", "Unknown", PROPER(TRIM(Raw_Data!$C42))) -> San Diego | E42: =IF(TRIM(Raw_Data!$D42)="IT","IT",PROPER(TRIM(CLEAN(Raw_Data!$D42)))) -> Production | F42: =IF(OR(UPPER(TRIM(Raw_Data!E42))="COO", UPPER(TRIM(Raw_Data!E42))="HR", UPPER(TRIM(Raw_Data!E42))="CEO", UPPER(TRIM(Raw_Data!E42))="CFO", UPPER(TRIM(Raw_Data!E42))="CMO"), UPPER(TRIM(Raw_Data!E42)), PROPER(TRIM(CLEAN(Raw_Data!E42)))) -> CFO | G42: =SUBSTITUTE(PROPER(TRIM(CLEAN(Raw_Data!$F42)))," ","-") -> Hourly-Rate | H42: =PROPER(TRIM(CLEAN(Raw_Data!$G42))) -> Organic | I42: =TRIM(CLEAN(Raw_Data!H42)) -> 40426 | K42: =IF(Clean_Data!$I42="","Active","Exited") -> Active | L42: =IF(Clean_Data!$K42="","",DATEDIF(Clean_Data!$K42,TODAY(),"Y")) -> 43 | M42: =IF(Raw_Data!$L42="","",VALUE(SUBSTITUTE(SUBSTITUTE(TRIM(Raw_Data!$L42),"$",""),"k","000"))) -> 55211
...

Sheet Clean_Data
A1: Employee ID | B1: Gender | C1: Location | D1: Department | E1: Role | F1: ContractType | G1: Hire Source | H1: HireDate | I1: ExitDate | J1: Employee Status | K1: BirthDate | L1: Employee Age | M1: Salary | N1: Tenure
A2: E00001 | B2: Unknown | C2: New York | D2: IT | E2: Sales Executive | F2: Full-Time | G2: Career Fairs | H2: 40644 | J2: Active | K2: 38567 | L2: 20 | M2: 116056 | N2: =ROUND((IF(I2="",TODAY(),I2)-H2)/365,1) -> 15
A3: E00002 | B3: Male | C3: Austin | D3: Research | E3: Sales Executive | F3: Full-Time | G3: Unknown | H3: 40461 | J3: Active | K3: 27505 | L3: 50 | M3: 55000 | N3: =ROUND((IF(I3="",TODAY(),I3)-H3)/365,1) -> 15.5
A4: E00003 | B4: Female | C4: Seattle | D4: Operations | E4: COO | F4: Part-Time | G4: Recruiting Agency | H4: 42794 | J4: Active | K4: 24668 | L4: 58 | N4: =ROUND((IF(I4="",TODAY(),I4)-H4)/365,1) -> 9.1
A5: E00004 | B5: Unknown | C5: Austin | D5: IT | E5: Developer | F5: Full-Time | G5: Unknown | H5: 40096 | J5: Active | K5: 24231 | L5: 59 | M5: 43000 | N5: =ROUND((IF(I5="",TODAY(),I5)-H5)/365,1) -> 16.5
A6: E00005 | B6: Male | C6: Denver | D6: IT | E6: Marketing Manager | F6: Full-Time | G6: Career Fairs | H6: 39983 | J6: Active | K6: 23144 | L6: 62 | N6: =ROUND((IF(I6="",TODAY(),I6)-H6)/365,1) -> 16.8
A7: E00006 | B7: Unknown | C7: Unknown | D7: Administrative | E7: Developer | F7: Full-Time | G7: Job Boards | H7: 43104 | J7: Active | K7: 27832 | L7: 50 | M7: 112467 | N7: =ROUND((IF(I7="",TODAY(),I7)-H7)/365,1) -> 8.2
A8: E00007 | B8: Unknown | C8: Austin | D8: IT | E8: Copywriter | F8: Part-Time | G8: Job Boards | H8: 41319 | I8: 42882 | J8: Exited | N8: =ROUND((IF(I8="",TODAY(),I8)-H8)/365,1) -> 4.3
A9: E00008 | B9: Female | C9: New York | D9: Legal | E9: Developer | F9: Unknown | G9: Job Boards | H9: 43023 | I9: 44345 | J9: Exited | K9: 34583 | L9: 31 | M9: 111222 | N9: =ROUND((IF(I9="",TODAY(),I9)-H9)/365,1) -> 3.6
A10: E00009 | B10: Unknown | C10: Unknown | D10: Customer Service | E10: Analyst | F10: Part-Time | G10: Job Boards | H10: 43223 | J10: Active | K10: 28678 | L10: 47 | M10: 108356 | N10: =ROUND((IF(I10="",TODAY(),I10)-H10)/365,1) -> 7.9
A11: E00010 | B11: Male | C11: New York | D11: Marketing | E11: Developer | F11: Hourly Rate | G11: Job Boards | H11: 40250 | I11: 40485 | J11: Exited | K11: 33563 | L11: 34 | M11: 40000 | N11: =ROUND((IF(I11="",TODAY(),I11)-H11)/365,1) -> 0.6
A12: E00011 | B12: Unknown | C12: Austin | D12: Unknown | E12: Engineer | F12: Unknown | G12: Online Portal | H12: 42580 | I12: 44498 | J12: Exited | M12: 107109 | N12: =ROUND((IF(I12="",TODAY(),I12)-H12)/365,1) -> 5.3
A13: E00012 | B13: Female | C13: Unknown | D13: Sales | E13: Marketing Manager | F13: Unknown | G13: Internal Referral | H13: 42290 | J13: Active | M13: 35000 | N13: =ROUND((IF(I13="",TODAY(),I13)-H13)/365,1) -> 10.4
A14: E00013 | B14: Female | C14: Unknown | D14: Administrative | E14: Marketing Manager | F14: Full-Time | G14: Unknown | H14: 42813 | J14: Active | K14: 22130 | L14: 65 | M14: 79318 | N14: =ROUND((IF(I14="",TODAY(),I14)-H14)/365,1) -> 9
A15: E00015 | B15: Female | C15: Austin | D15: Customer Service | E15: Engineer | F15: Full-Time | G15: Career Fairs | H15: 44154 | J15: Active | K15: 26131 | L15: 54 | M15: 75703 | N15: =ROUND((IF(I15="",TODAY(),I15)-H15)/365,1) -> 5.3
A16: E00017 | B16: Unknown | C16: Miami | D16: Marketing | E16: Developer | F16: Full-Time | G16: Organic | H16: 40093 | J16: Active | K16: 33946 | L16: 33 | M16: 66358 | N16: =ROUND((IF(I16="",TODAY(),I16)-H16)/365,1) -> 16.5
A17: E00018 | B17: Male | C17: New York | D17: Unknown | E17: HR Manager | F17: Full-Time | G17: Unknown | H17: 39865 | I17: 41288 | J17: Exited | K17: 33757 | L17: 33 | N17: =ROUND((IF(I17="",TODAY(),I17)-H17)/365,1) -> 3.9
A18: E00019 | B18: Female | C18: Unknown | D18: Marketing | E18: CFO | F18: Full-Time | G18: Job Boards | H18: 42319 | J18: Active | K18: 34621 | L18: 31 | M18: 80005 | N18: =ROUND((IF(I18="",TODAY(),I18)-H18)/365,1) -> 10.4
A19: E00020 | B19: Male | C19: New York | D19: IT | E19: Engineer | F19: Unknown | G19: Organic | H19: 41906 | I19: 42277 | J19: Exited | K19: 38387 | L19: 21 | N19: =ROUND((IF(I19="",TODAY(),I19)-H19)/365,1) -> 1
A20: E00022 | B20: Male | C20: Unknown | D20: Logistics | E20: Developer | F20: Part-Time | G20: Unknown | H20: 41005 | J20: Active | K20: 24098 | L20: 60 | M20: 49491 | N20: =ROUND((IF(I20="",TODAY(),I20)-H20)/365,1) -> 14
A21: E00023 | B21: Female | C21: San Diego | D21: Administrative | E21: Copywriter | F21: Full-Time | G21: Career Fairs | H21: 43786 | J21: Active | K21: 31255 | L21: 40 | N21: =ROUND((IF(I21="",TODAY(),I21)-H21)/365,1) -> 6.3
A22: E00024 | B22: Unknown | C22: San Diego | D22: Marketing | E22: CEO | F22: Unknown | G22: Unknown | H22: 41033 | J22: Active | K22: 27366 | L22: 51 | M22: 90148 | N22: =ROUND((IF(I22="",TODAY(),I22)-H22)/365,1) -> 13.9
A23: E00025 | B23: Female | C23: New York | D23: Marketing | E23: Developer | F23: Unknown | G23: Unknown | H23: 43268 | I23: 44640 | J23: Exited | K23: 25689 | L23: 55 | N23: =ROUND((IF(I23="",TODAY(),I23)-H23)/365,1) -> 3.8
A24: E00026 | B24: Male | C24: Unknown | D24: Unknown | E24: CFO | F24: Part-Time | G24: Internal Referral | H24: 43530 | I24: 45319 | J24: Exited | K24: 23460 | L24: 61 | M24: 110000 | N24: =ROUND((IF(I24="",TODAY(),I24)-H24)/365,1) -> 4.9
A25: E00027 | B25: Unknown | C25: Austin | D25: IT | E25: CMO | F25: Unknown | G25: Career Fairs | H25: 43015 | J25: Active | M25: 83205 | N25: =ROUND((IF(I25="",TODAY(),I25)-H25)/365,1) -> 8.5
A26: E00028 | B26: Female | C26: Austin | D26: Research | E26: CEO | F26: Unknown | G26: Job Boards | H26: 43799 | J26: Active | K26: 28077 | L26: 49 | N26: =ROUND((IF(I26="",TODAY(),I26)-H26)/365,1) -> 6.3
A27: E00029 | B27: Female | C27: San Diego | D27: Administrative | E27: Engineer | F27: Unknown | G27: Internal Referral | H27: 41064 | I27: 42846 | J27: Exited | K27: 27368 | L27: 51 | M27: 76000 | N27: =ROUND((IF(I27="",TODAY(),I27)-H27)/365,1) -> 4.9
A28: E00031 | B28: Male | C28: Austin | D28: Sales | E28: Analyst | F28: Unknown | G28: Career Fairs | H28: 39845 | J28: Active | K28: 30079 | L28: 43 | N28: =ROUND((IF(I28="",TODAY(),I28)-H28)/365,1) -> 17.1
A29: E00032 | B29: Male | C29: Austin | D29: Marketing | E29: HR Manager | F29: Part-Time | G29: Organic | H29: 41099 | I29: 41752 | J29: Exited | K29: 29578 | L29: 45 | M29: 61880 | N29: =ROUND((IF(I29="",TODAY(),I29)-H29)/365,1) -> 1.8
A30: E00033 | B30: Male | C30: San Diego | D30: Administrative | E30: Unknown | F30: Part-Time | G30: Job Boards | H30: 40487 | J30: Active | K30: 23735 | L30: 61 | N30: =ROUND((IF(I30="",TODAY(),I30)-H30)/365,1) -> 15.4
A31: E00034 | B31: Female | C31: Austin | D31: Legal | E31: Accountant | F31: Unknown | G31: Online Portal | H31: 43357 | J31: Active | K31: 37123 | L31: 24 | M31: 59000 | N31: =ROUND((IF(I31="",TODAY(),I31)-H31)/365,1) -> 7.5
A32: E00035 | B32: Unknown | C32: Miami | D32: IT | E32: CFO | F32: Unknown | G32: Career Fairs | H32: 43073 | I32: 43442 | J32: Exited | K32: 23623 | L32: 61 | N32: =ROUND((IF(I32="",TODAY(),I32)-H32)/365,1) -> 1
A33: E00036 | B33: Female | C33: Miami | D33: Operations | E33: Accountant | F33: Part-Time | G33: Recruiting Agency | H33: 42211 | J33: Active | K33: 36512 | L33: 26 | M33: 31000 | N33: =ROUND((IF(I33="",TODAY(),I33)-H33)/365,1) -> 10.7
A34: E00037 | B34: Female | C34: Austin | D34: IT | E34: Unknown | F34: Hourly Rate | G34: Career Fairs | H34: 39948 | J34: Active | K34: 29201 | L34: 46 | M34: 77517 | N34: =ROUND((IF(I34="",TODAY(),I34)-H34)/365,1) -> 16.9
A35: E00038 | B35: Female | C35: Denver | D35: Marketing | E35: Unknown | F35: Full-Time | G35: Unknown | H35: 44034 | J35: Active | K35: 37775 | L35: 22 | M35: 85503 | N35: =ROUND((IF(I35="",TODAY(),I35)-H35)/365,1) -> 5.7
A36: E00039 | B36: Male | C36: New York | D36: Production | E36: Analyst | F36: Hourly Rate | G36: Job Boards | H36: 42557 | I36: 42695 | J36: Exited | K36: 36236 | L36: 26 | N36: =ROUND((IF(I36="",TODAY(),I36)-H36)/365,1) -> 0.4
A37: E00040 | B37: Male | C37: San Diego | D37: Logistics | E37: CEO | F37: Unknown | G37: Recruiting Agency | H37: 41683 | I37: 43118 | J37: Exited | K37: 23433 | L37: 62 | M37: 63023 | N37: =ROUND((IF(I37="",TODAY(),I37)-H37)/365,1) -> 3.9
A38: E00041 | B38: Female | C38: San Diego | D38: Production | E38: CFO | F38: Hourly Rate | G38: Organic | H38: 40426 | I38: 41976 | J38: Exited | K38: 22851 | L38: 63 | N38: =ROUND((IF(I38="",TODAY(),I38)-H38)/365,1) -> 4.2
A39: E00042 | B39: Female | C39: Miami | D39: Human Resources | E39: Marketing Manager | F39: Hourly Rate | G39: Organic | H39: 40459 | J39: Active | K39: 31082 | L39: 41 | N39: =ROUND((IF(I39="",TODAY(),I39)-H39)/365,1) -> 15.5
A40: E00043 | B40: Female | C40: Unknown | D40: Research | E40: Copywriter | F40: Full-Time | G40: Recruiting Agency | H40: 43954 | J40: Active | K40: 31872 | L40: 38 | M40: 51000 | N40: =ROUND((IF(I40="",TODAY(),I40)-H40)/365,1) -> 5.9
...
